{"Message":"An error has occurred.","ExceptionMessage":"One or more errors occurred.","ExceptionType":"System.AggregateException","StackTrace":"   at System.Threading.Tasks.Task`1.GetResultCore(Boolean waitCompletionNotification)\r\n   at ClassLibrary2.CustomWebAPIController.Getxml(String applicationNumber) in E:\\Eurobank\\Eurobank-Extranet\\DevV2\\ClassLibrary2\\CustomWebAPIController.cs:line 40\r\n   at ClassLibrary2.CustomWebAPIController.Get(String applicationNumber) in E:\\Eurobank\\Eurobank-Extranet\\DevV2\\ClassLibrary2\\CustomWebAPIController.cs:line 24\r\n   at lambda_method(Closure , Object , Object[] )\r\n   at System.Web.Http.Controllers.ReflectedHttpActionDescriptor.ActionExecutor.<>c__DisplayClass10.<GetExecutor>b__9(Object instance, Object[] methodParameters)\r\n   at System.Web.Http.Controllers.ReflectedHttpActionDescriptor.ExecuteAsync(HttpControllerContext controllerContext, IDictionary`2 arguments, CancellationToken cancellationToken)\r\n--- End of stack trace from previous location where exception was thrown ---\r\n   at System.Runtime.ExceptionServices.ExceptionDispatchInfo.Throw()\r\n   at System.Runtime.CompilerServices.TaskAwaiter.HandleNonSuccessAndDebuggerNotification(Task task)\r\n   at System.Web.Http.Controllers.ApiControllerActionInvoker.<InvokeActionAsyncCore>d__0.MoveNext()\r\n--- End of stack trace from previous location where exception was thrown ---\r\n   at System.Runtime.ExceptionServices.ExceptionDispatchInfo.Throw()\r\n   at System.Runtime.CompilerServices.TaskAwaiter.HandleNonSuccessAndDebuggerNotification(Task task)\r\n   at System.Web.Http.Filters.ActionFilterAttribute.<CallOnActionExecutedAsync>d__5.MoveNext()\r\n--- End of stack trace from previous location where exception was thrown ---\r\n   at System.Runtime.ExceptionServices.ExceptionDispatchInfo.Throw()\r\n   at System.Web.Http.Filters.ActionFilterAttribute.<CallOnActionExecutedAsync>d__5.MoveNext()\r\n--- End of stack trace from previous location where exception was thrown ---\r\n   at System.Runtime.ExceptionServices.ExceptionDispatchInfo.Throw()\r\n   at System.Runtime.CompilerServices.TaskAwaiter.HandleNonSuccessAndDebuggerNotification(Task task)\r\n   at System.Web.Http.Filters.ActionFilterAttribute.<ExecuteActionFilterAsyncCore>d__0.MoveNext()\r\n--- End of stack trace from previous location where exception was thrown ---\r\n   at System.Runtime.ExceptionServices.ExceptionDispatchInfo.Throw()\r\n   at System.Runtime.CompilerServices.TaskAwaiter.HandleNonSuccessAndDebuggerNotification(Task task)\r\n   at System.Web.Http.Controllers.ActionFilterResult.<ExecuteAsync>d__2.MoveNext()\r\n--- End of stack trace from previous location where exception was thrown ---\r\n   at System.Runtime.ExceptionServices.ExceptionDispatchInfo.Throw()\r\n   at System.Runtime.CompilerServices.TaskAwaiter.HandleNonSuccessAndDebuggerNotification(Task task)\r\n   at System.Web.Http.Dispatcher.HttpControllerDispatcher.<SendAsync>d__1.MoveNext()","InnerException":{"Message":"An error has occurred.","ExceptionMessage":"An error occurred while sending the request.","ExceptionType":"System.Net.Http.HttpRequestException","StackTrace":null,"InnerException":{"Message":"An error has occurred.","ExceptionMessage":"Unable to connect to the remote server","ExceptionType":"System.Net.WebException","StackTrace":"   at System.Net.HttpWebRequest.EndGetResponse(IAsyncResult asyncResult)\r\n   at System.Net.Http.HttpClientHandler.GetResponseCallback(IAsyncResult ar)","InnerException":{"Message":"An error has occurred.","ExceptionMessage":"No connection could be made because the target machine actively refused it 127.0.0.1:106","ExceptionType":"System.Net.Sockets.SocketException","StackTrace":"   at System.Net.Sockets.Socket.InternalEndConnect(IAsyncResult asyncResult)\r\n   at System.Net.Sockets.Socket.EndConnect(IAsyncResult asyncResult)\r\n   at System.Net.ServicePoint.ConnectSocketInternal(Boolean connectFailure, Socket s4, Socket s6, Socket& socket, IPAddress& address, ConnectSocketState state, IAsyncResult asyncResult, Exception& exception)"}}}}